Workbook
Name \0: #REF!
Name \b: #N/A
Name \C: #REF!
Name \D: #REF!
Name \D: #REF!
Name \D: #REF!
Name \E: #REF!
Name IQ_CH: 110000
Name IQ_CQ: 5000
Name IQ_CY: 10000
Name IQ_DAILY: 500000
Name IQ_FH: 100000
Name IQ_FQ: 500
Name IQ_FY: 1000
Name IQ_LTM: 2000
Name IQ_MONTH: 15000
Name IQ_NTM: 6000
Name IQ_WEEK: 50000
Name IQ_YTD: 3000

Sheet 结果对比
C8: 人民币万元 | D8: 可比P/E - 25年0.8亿利润 | E8: 可比P/E - 26年1.0亿利润 | F8: DCF
C9: 低端 | D9: =市场法!E24 -> 10.468504 | E9: =1.02/0.83*D9 -> 12.864908 | F9: =DCF!F43 -> 10.635737
C10: 增量 | D10: =D11-D9 -> 18.993298 | E10: =E11-E9 -> 23.341161 | F10: =F11-F9 -> 11.837951
C11: 高端 | D11: =市场法!F24 -> 29.461801 | E11: =1.02/0.83*D11 -> 36.206069 | F11: =DCF!H45 -> 22.473688

Sheet DCF
B2: 目标公司 | C2: 锐洁机器人 | F2: 57800 | G2: 73500
B3: 估值时点 | C3: 46097
B5: 万元 | C5: 2024A | D5: 2025A | E5: 2026E | F5: 2027E | G5: 2028E | H5: 2029E | I5: 2030E | J5: CAGR | L5: 2024A | M5: 2025A | N5: 2026E | O5: 2027E | P5: 2028E | Q5: 2029E | R5: 2030E
B6: 营业收入 | C6: =锐洁利润表!B3 -> 37320.201 | D6: =锐洁利润表!M3/10 -> 43221.542 | E6: =锐洁利润表!D3 -> 57800 | F6: =锐洁利润表!F3 -> 73500 | G6: =F6*(1+G7) -> 91875 | H6: =G6*(1+H7) -> 114843.75 | I6: =D6*(1+J7)^5 -> 131901.68 | L6: =C6/C$6 -> 1 | M6: =D6/D$6 -> 1 | N6: =E6/E$6 -> 1 | O6: =F6/F$6 -> 1 | P6: =G6/G$6 -> 1 | Q6: =H6/H$6 -> 1 | R6: =I6/I$6 -> 1
B7: YoY | D7: =D6/C6-1 -> 0.15812725 | E7: =E6/D6-1 -> 0.33729612 | F7: =F6/E6-1 -> 0.2716263 | G7: 0.25 | H7: 0.25 | I7: 0.2 | J7: 0.25
B8: 营业成本 | C8: =锐洁利润表!B10 -> -21536.016 | D8: =锐洁利润表!C10 -> -24514.496 | E8: =锐洁利润表!D10 -> -33524 | F8: =锐洁利润表!F10 -> -43365 | G8: =G9-G6 -> -54206.25 | H8: =H9-H6 -> -67757.812 | I8: =I9-I6 -> -77821.99 | L8: =C8/C$6 -> -0.57706055 | M8: =D8/D$6 -> -0.56718237 | N8: =E8/E$6 -> -0.58 | O8: =F8/F$6 -> -0.59 | P8: =G8/G$6 -> -0.59 | Q8: =H8/H$6 -> -0.59 | R8: =I8/I$6 -> -0.59
B9: 毛利 | C9: =锐洁利润表!L5/10 -> 15784.185 | D9: =锐洁利润表!M5/10 -> 18707.045 | E9: =E6*锐洁利润表!D16 -> 24276 | F9: =F6*锐洁利润表!F16 -> 30135 | G9: =G6*P9 -> 37668.75 | H9: =H6*Q9 -> 47085.938 | I9: =I6*R9 -> 54079.688 | L9: =C9/C$6 -> 0.42293945 | M9: =D9/D$6 -> 0.43281763 | N9: =E9/E$6 -> 0.42 | O9: =F9/F$6 -> 0.41 | P9: 0.41 | Q9: 0.41 | R9: 0.41
B10: 税金及附加 | C10: =锐洁利润表!L6/10 -> -31.241087 | D10: =锐洁利润表!M6/10 -> -225.2439 | L10: =C10/C$6 -> -0.00083710929 | M10: =D10/D$6 -> -0.0052113805 | N10: =E10/E$6 -> 0 | O10: =F10/F$6 -> 0 | P10: =G10/G$6 -> 0 | Q10: =H10/H$6 -> 0 | R10: =I10/I$6 -> 0
B11: 销售费用 | C11: =锐洁利润表!L7/10 -> -1602.4355 | D11: =锐洁利润表!M7/10 -> -2100.9406 | E11: =锐洁利润表!D18 -> -3179 | F11: =锐洁利润表!F18 -> -4042.5 | G11: =G6*P11 -> -4593.75 | H11: =H6*Q11 -> -4593.75 | I11: =I6*R11 -> -5276.0671 | L11: =C11/C$6 -> -0.042937482 | M11: =D11/D$6 -> -0.048608646 | N11: =E11/E$6 -> -0.055 | O11: =F11/F$6 -> -0.055 | P11: -0.05 | Q11: -0.04 | R11: -0.04
B12: 管理费用 | C12: =锐洁利润表!L8/10 -> -1767.5833 | D12: =锐洁利润表!M8/10 -> -2159.0286 | E12: =锐洁利润表!D19 -> -3468 | F12: =锐洁利润表!F19 -> -4410 | G12: =G6*P12 -> -5512.5 | H12: =H6*Q12 -> -6890.625 | I12: =I6*R12 -> -7914.1007 | L12: =C12/C$6 -> -0.047362641 | M12: =D12/D$6 -> -0.049952605 | N12: =E12/E$6 -> -0.06 | O12: =F12/F$6 -> -0.06 | P12: -0.06 | Q12: -0.06 | R12: -0.06
B13: 研发费用 | C13: =锐洁利润表!L9/10 -> -4380.3072 | D13: =锐洁利润表!M9/10 -> -5619.2907 | E13: =锐洁利润表!D20 -> -6473.6 | F13: =锐洁利润表!F20 -> -8305.5 | G13: =G6*P13 -> -9187.5 | H13: =H6*Q13 -> -9761.7188 | I13: =I6*R13 -> -9233.1175 | L13: =C13/C$6 -> -0.11737094 | M13: =D13/D$6 -> -0.13001134 | N13: =E13/E$6 -> -0.112 | O13: =F13/F$6 -> -0.113 | P13: -0.1 | Q13: -0.085 | R13: -0.07
B14: 其他
B15: 经营利润 | C15: =锐洁利润表!L13/10 -> 8934.6314 | D15: =锐洁利润表!M13/10 -> 9118.8221 | E15: =SUM(E9:E14) -> 11155.4 | F15: =SUM(F9:F14) -> 13377 | G15: =SUM(G9:G14) -> 18375 | H15: =SUM(H9:H14) -> 25839.844 | I15: =SUM(I9:I14) -> 31656.403 | L15: =C15/C$6 -> 0.2394047 | M15: =D15/D$6 -> 0.21097864 | N15: =E15/E$6 -> 0.193 | O15: =F15/F$6 -> 0.182 | P15: =G15/G$6 -> 0.2 | Q15: =H15/H$6 -> 0.225 | R15: =I15/I$6 -> 0.24
B16: 所得税费用 | C16: =锐洁利润表!L17/10 -> -1025.9757 | D16: =锐洁利润表!M17/10 -> -468.29894 | E16: =E17-E15 -> -937.2 | F16: =-F15*0.15 -> -2006.55 | G16: =-G15*0.15 -> -2756.25 | H16: =-H15*0.15 -> -3875.9766 | I16: =-I15*0.15 -> -4748.4604 | L16: =C16/C$6 -> -0.027491161 | M16: =D16/D$6 -> -0.01083485 | N16: =E16/E$6 -> -0.016214533 | O16: =F16/F$6 -> -0.0273 | P16: =G16/G$6 -> -0.03 | Q16: =H16/H$6 -> -0.03375 | R16: =I16/I$6 -> -0.036
B17: 净利润 | C17: =锐洁利润表!B22 -> 7911.5288 | D17: =锐洁利润表!C22 -> 8326.0707 | E17: =锐洁利润表!D22 -> 10218.2 | F17: =锐洁利润表!F22 -> 12163 | G17: =G15+G16 -> 15618.75 | H17: =H15+H16 -> 21963.867 | I17: =I15+I16 -> 26907.942 | L17: =C17/C$6 -> 0.21199052 | M17: =D17/D$6 -> 0.19263706 | N17: =E17/E$6 -> 0.17678547 | O17: =F17/F$6 -> 0.16548299 | P17: =G17/G$6 -> 0.17 | Q17: =H17/H$6 -> 0.19125 | R17: =I17/I$6 -> 0.204
B18: 减去：资本性支出 | C18: -266.17477 | D18: -1178.1015 | E18: -1000 | F18: -1000 | G18: -1000 | H18: -1000 | I18: -1000
B19: 加回:折旧摊销
B20: 营运资本 | C20: 22387.53 | D20: 29786.983 | E20: =E6*(120/360)+(30/360)*E8-(250/360)*E8 -> 39753.556 | F20: =F6*(120/360)+(30/360)*F8-(250/360)*F8 -> 51000.833 | G20: =G6*(120/360)+(30/360)*G8-(250/360)*G8 -> 63751.042 | H20: =H6*(120/360)+(30/360)*H8-(250/360)*H8 -> 79688.802 | I20: =I6*(120/360)+(30/360)*I8-(250/360)*I8 -> 91525.109 | L20: =C20/C$6 -> 0.59987699 | M20: =D20/D$6 -> 0.68916985 | N20: =E20/E$6 -> 0.68777778 | O20: =F20/F$6 -> 0.69388889 | P20: =G20/G$6 -> 0.69388889 | Q20: =H20/H$6 -> 0.69388889 | R20: =I20/I$6 -> 0.69388889 | S20: 行业70%
B21: 减去：营运资本增加 | C21: 2090.9899 | D21: =-(D20-C20) -> -7399.4535 | E21: =-(E20-D20) -> -9966.5721 | F21: =-(F20-E20) -> -11247.278 | G21: =-(G20-F20) -> -12750.208 | H21: =-(H20-G20) -> -15937.76 | I21: =-(I20-H20) -> -11836.307
B22: 自由现金流 | C22: =C17+C18+C19+C21 -> 9736.3439 | D22: =D17+D18+D19+D21 -> -251.48427 | E22: =E17+E18+E19+E21 -> -748.37209 | F22: =F17+F18+F19+F21 -> -84.277778 | G22: =G17+G18+G19+G21 -> 1868.5417 | H22: =H17+H18+H19+H21 -> 5026.1068 | I22: =I17+I18+I19+I21 -> 14071.636
B23: 折现 | C23: 1 | D23: 2 | E23: 3 | F23: 4 | G23: 5 | H23: 6 | I23: 7
B24: 折线因子 | C24: =1/(1+$C$28)^C23 -> 0.76923077 | D24: =1/(1+$C$28)^D23 -> 0.59171598 | E24: =1/(1+$C$28)^E23 -> 0.45516614 | F24: =1/(1+$C$28)^F23 -> 0.3501278 | G24: =1/(1+$C$28)^G23 -> 0.26932907 | H24: =1/(1+$C$28)^H23 -> 0.20717621 | I24: =1/(1+$C$28)^I23 -> 0.15936632
B25: 自由现金流现值 | C25: =C22*C24 -> 7489.4953 | D25: =D22*D24 -> -148.80726 | E25: =E22*E24 -> -340.63363 | F25: =F22*F24 -> -29.507993 | G25: =G22*G24 -> 503.2526 | H25: =H22*H24 -> 1041.2898 | I25: =I22*I24 -> 2242.5447
B27: 企业价值分析 | C27: 人民币万元
B28: 折现率 | C28: 0.3
B29: 预测期企业自由现金流现值 | C29: =SUM(C25:I25) -> 10757.634
B30: 退出P/E倍数 | C30: 40
B31: 终值现值 | C31: =C30*I17*I24 -> 171528.79
B32: 企业价值_调整前 | C32: =C29+C31 -> 182286.42
B33: 净负债 | C33: 21676
B34: 股东权益价值 | C34: =C32-C33 -> 160610.42
B35: 估值 | C35: =C34/10000 -> 16.061042
B38: 敏感性分析
C39: 估值 | E39: 收入复合增长
D40: 收入 | E40: =$D$6*(1+E41)^5 -> 107549.03 | F40: =$D$6*(1+F41)^5 -> 119228.67 | G40: =$D$6*(1+G41)^5 -> 131901.68 | H40: =$D$6*(1+H41)^5 -> 145630.11 | I40: =$D$6*(1+I41)^5 -> 160478.56
D41: =C35 -> 16.061042 | E41: 0.2 | F41: 0.225 | G41: 0.25 | H41: 0.275 | I41: 0.3 | L41: 预期净利润 | M41: =I17 -> 26907.942
C42: P/E | D42: 20 | E42: 6.0912833 | F42: 6.7595256 | G42: 7.4846026 | H42: 8.270065 | I42: 9.1196083 | L42: 退出倍数 | M42: =C30 -> 40
D43: 30 | E43: 9.5877805 | F43: 10.635737 | G43: 11.772822 | H43: 13.004606 | I43: 14.336883 | L43: 退出市值 | M43: =M41*M42 -> 1076317.7
D44: 40 | E44: 13.084278 | F44: 14.511947 | G44: 16.061042 | H44: 17.739147 | I44: 19.554158 | L44: 本轮投资成本 | M44: 3000
D45: 50 | E45: 16.580775 | F45: 18.388158 | G45: 20.349262 | H45: 22.473688 | I45: 24.771433 | L45: 本轮投后股比 | M45: =3000/145000 -> 0.020689655
...

Sheet 市场法
B2: 可比公司 | C2: 股票代码 | D2: 主要业务 | E2: 可比程度判定 | F2: FY25营业收入 | G2: FY25毛利率 | H2: FY25销售费用率 | I2: FY25管理费用率 | J2: FY25研发费用率 | K2: DSO | L2: DPO | M2: DIO | N2: P/S | O2: PSG | P2: P/E | Q2: 是否选入倍数POOL
B3: 富创精密 | C3: 688409 | D3: 半导体设备的精密零部件制造。 | E3: 强 | F3: 27.301527 | G3: 0.020913739 | H3: 0.021964119 | I3: 0.1148805 | J3: 0.071530468 | K3: =可比公司营运情况!H3 -> 118.61091 | L3: =可比公司营运情况!L3 -> 147.66495 | M3: =可比公司营运情况!P3 -> 111.1752 | N3: 89.89 | O3: =N3/'二级可比 相对估值'!K23 -> 68.384991 | P3: 6.38 | Q3: Y
B4: 先锋精科 | C4: 688605 | D4: 半导体刻蚀和薄膜沉积设备细分领域关键零部件的精密制造。 | E4: 中 | F4: 9.685596 | G4: 0.19703134 | H4: 0.0044200687 | I4: 0.041294516 | J4: 0.055357461 | K4: =可比公司营运情况!H4 -> 95.781086 | L4: =可比公司营运情况!L4 -> 46.130894 | M4: =可比公司营运情况!P4 -> 157.8394 | N4: 63.8 | P4: 10.64 | Q4: Y
B5: 神工股份 | C5: 688233 | D5: 集成电路刻蚀用单晶硅材料的研发、生产和销售。 | E5: 中 | F5: 3.159998 | G5: 0.28905366 | H5: 0.016747479 | I5: 0.070224412 | J5: 0.067547195 | K5: =可比公司营运情况!H5 -> 127.47673 | L5: =可比公司营运情况!L5 -> 110.92694 | M5: =可比公司营运情况!P5 -> 240.3632 | N5: 51.14 | O5: =N5/'二级可比 相对估值'!K25 -> 34.194561 | P5: 18.64 | Q5: Y
B6: 凯德石英 | C6: 835179 | D6: 石英仪器、石英管道、石英舟等石英玻璃制品的生产、研发和销售 | E6: 弱 | F6: 2.221241 | G6: 0.14638934 | H6: 0.020823044 | I6: 0.17659047 | J6: 0.069565617 | K6: =可比公司营运情况!H6 -> 95.203838 | L6: =可比公司营运情况!L6 -> 138.586 | M6: =可比公司营运情况!P6 -> 170.9618 | N6: 34.87 | O6: =N6/'二级可比 相对估值'!K26 -> 34.0153 | P6: 8.1 | Q6: Y
B7: 江丰电子 | C7: 300666 | D7: 高纯溅射靶材的研发、生产和销售业务 | E7: 强 | F7: 32.911562 | G7: 0.11898749 | H7: 0.026502176 | I7: 0.064743174 | J7: 0.058975536 | K7: =可比公司营运情况!H7 -> 89.044889 | L7: =可比公司营运情况!L7 -> 32.130407 | M7: =可比公司营运情况!P7 -> 532.4394 | N7: 63.54 | O7: =N7/'二级可比 相对估值'!K27 -> 49.935654 | P7: 6.875 | Q7: Y
B8: 英杰电气 | C8: 300820 | D8: 以功率控制电源、特种电源为代表的工业电源设备的研发、生产、销售 | E8: 中 | F8: 11.497447 | G8: 0.1851191 | H8: 0.046868927 | I8: 0.032160879 | J8: 0.096441236 | K8: =可比公司营运情况!H8 -> 129.01739 | L8: =可比公司营运情况!L8 -> 187.90692 | M8: =可比公司营运情况!P8 -> 499.6299 | N8: 40.15 | O8: =N8/'二级可比 相对估值'!K28 -> 38.931274 | P8: 8.265 | Q8: Y
B9: 机器人 | C9: 300024 | D9: 零部件、机器人、特种机器人及工业4.0 | E9: 中 | F9: 22.184812 | G9: -0.091215017 | H9: 0.039455462 | I9: 0.10048091 | J9: 0.067337285 | K9: =可比公司营运情况!H9 -> 109.92187 | L9: =可比公司营运情况!L9 -> 111.02234 | M9: =可比公司营运情况!P9 -> 242.3916 | N9: -22.44 | P9: 5.3 | Q9: Y
B10: 新莱应材 | C10: 300260 | D10: 以高纯不锈钢为母材之高洁净应用材料研发、生产与销售 | E10: 弱 | F10: 22.545876 | G10: 0.075145982 | H10: 0.060988094 | I10: 0.046580537 | J10: 0.038639439 | K10: =可比公司营运情况!H10 -> 169.42977 | L10: =可比公司营运情况!L10 -> 83.305287 | M10: =可比公司营运情况!P10 -> 123.282 | N10: 49.96 | O10: =N10/'二级可比 相对估值'!K30 -> 47.745045 | P10: 4.83 | Q10: Y
B11: 创业板估值
B12: 最小值 | G12: {=MIN(IF($Q$3:$Q$10="Y",G$3:G$10))} -> -0.091215017 | H12: {=MIN(IF($Q$3:$Q$10="Y",H$3:H$10))} -> 0.0044200687 | I12: {=MIN(IF($Q$3:$Q$10="Y",I$3:I$10))} -> 0.032160879 | J12: {=MIN(IF($Q$3:$Q$10="Y",J$3:J$10))} -> 0.038639439 | K12: {=MIN(IF($Q$3:$Q$10="Y",K$3:K$10))} -> 89.044889 | L12: {=MIN(IF($Q$3:$Q$10="Y",L$3:L$10))} -> 32.130407 | M12: {=MIN(IF($Q$3:$Q$10="Y",M$3:M$10))} -> 111.1752 | N12: {=MIN(IF($Q$3:$Q$10="Y",N$3:N$10))} -> -22.44 | ... P12: {=MIN(IF($Q$3:$Q$10="Y",P$3:P$10))} -> 4.83
B13: 最大值 | G13: {=MAX(IF($Q$3:$Q$10="Y",G$3:G$10))} -> 0.28905366 | H13: {=MAX(IF($Q$3:$Q$10="Y",H$3:H$10))} -> 0.060988094 | I13: {=MAX(IF($Q$3:$Q$10="Y",I$3:I$10))} -> 0.17659047 | J13: {=MAX(IF($Q$3:$Q$10="Y",J$3:J$10))} -> 0.096441236 | K13: {=MAX(IF($Q$3:$Q$10="Y",K$3:K$10))} -> 169.42977 | L13: {=MAX(IF($Q$3:$Q$10="Y",L$3:L$10))} -> 187.90692 | M13: {=MAX(IF($Q$3:$Q$10="Y",M$3:M$10))} -> 532.4394 | N13: {=MAX(IF($Q$3:$Q$10="Y",N$3:N$10))} -> 89.89 | ... P13: {=MAX(IF($Q$3:$Q$10="Y",P$3:P$10))} -> 18.64
B14: 中位数 | G14: {=MEDIAN(IF($Q$3:$Q$10="Y",G$3:G$10))} -> 0.13268841 | H14: {=MEDIAN(IF($Q$3:$Q$10="Y",H$3:H$10))} -> 0.024233148 | I14: {=MEDIAN(IF($Q$3:$Q$10="Y",I$3:I$10))} -> 0.067483793 | J14: {=MEDIAN(IF($Q$3:$Q$10="Y",J$3:J$10))} -> 0.06744224 | K14: {=MEDIAN(IF($Q$3:$Q$10="Y",K$3:K$10))} -> 114.26639 | L14: {=MEDIAN(IF($Q$3:$Q$10="Y",L$3:L$10))} -> 110.97464 | M14: {=MEDIAN(IF($Q$3:$Q$10="Y",M$3:M$10))} -> 205.6625 | N14: {=MEDIAN(IF($Q$3:$Q$10="Y",N$3:N$10))} -> 50.55 | O14: {=MEDIAN(IF($Q$3:$Q$10="Y",O$3:O$10))} -> 36.562917 | P14: =MEDIAN(P3:P10) -> 7.4875
M16: =M14+K14 -> 319.92889
B17: 估值方法 | C17: P/S | E17: P/E
B18: 货币单位：人民币万元 | C18: 低端 | D18: 中位数 | E18: 低端 | F18: 中位数 | M18: =L14*0.6 -> 66.584783
B19: 市场倍数 | C19: ='二级可比 相对估值'!K15 -> 3.0421857 | D19: ='二级可比 相对估值'!K16 -> 7.4875 | E19: ='二级可比 相对估值'!K6 -> 17.96166 | F19: ='二级可比 相对估值'!K7 -> 50.55 | G19: <<选取可比程度为中和高的可比公司 | M19: =M16-M18 -> 253.34411
B20: 营业收入 | C20: =锐洁利润表!C3 -> 43221.542 | D20: =C20 -> 43221.542 | M20: =M19/360 -> 0.70373364
B21: 营业利润 | E21: =锐洁利润表!C22/10000 -> 0.83260707 | F21: =E21 -> 0.83260707
B22: 100%股东权益价值（具有控制权且流通基础） | C22: =C20*C19 -> 131487.95 | D22: =D20*D19 -> 323621.29 | E22: =E21*E19 -> 14.955005 | F22: =F21*F19 -> 42.088288
B23: 缺乏流动性折扣 | C23: 0.3 | D23: 0.3 | E23: 0.3 | F23: 0.3
B24: 100%股东权益价值（具有控制权且非流通基础） | C24: =C22*(1-C23) -> 92041.568 | D24: =D22*(1-D23) -> 226534.91 | E24: =E22*(1-E23) -> 10.468504 | F24: =F22*(1-F23) -> 29.461801

Sheet 二级可比 相对估值
B2: 数据源：2020.9-2026.3 PE倍数
B4: 可比公司
C5: 富创精密 | D5: 先锋精科 | E5: 神工股份 | F5: 凯德石英 | G5: 江丰电子 | H5: 英杰电气 | I5: 机器人 | J5: 新莱应材 | K5: 中位数
B6: -1倍标准差 | C6: =C7-Q32 -> 57.30166 | D6: =D7-Q32 -> 31.21166 | E6: =E7-Q32 -> 18.55166 | F6: =F7-Q32 -> 2.2816599 | G6: =G7-$Q$32 -> 30.95166 | H6: =H7-$Q$32 -> 7.5616599 | I6: =I7-$Q$32 -> -55.02834 | J6: =J7-$Q$32 -> 17.37166 | K6: =MEDIAN(C6:J6) -> 17.96166
B7: 中位数 | C7: =Q23 -> 89.89 | D7: =Q24 -> 63.8 | E7: =Q25 -> 51.14 | F7: =Q26 -> 34.87 | G7: =Q27 -> 63.54 | H7: =Q28 -> 40.15 | I7: =Q29 -> -22.44 | J7: =Q30 -> 49.96 | K7: =MEDIAN(C7:J7) -> 50.55
B8: +1倍标准差 | C8: =C7+Q32 -> 122.47834 | D8: =D7+Q32 -> 96.38834 | E8: =E7+Q32 -> 83.72834 | F8: =F7+Q32 -> 67.45834 | G8: =G7+Q32 -> 96.12834 | H8: =H7+Q32 -> 72.73834 | I8: =I7+Q32 -> 10.14834 | J8: =J7+Q32 -> 82.54834 | K8: =MEDIAN(C8:J8) -> 83.13834
B9: 最新 | C9: =P23 -> 553.41 | D9: =P24 -> 62.72 | E9: =P25 -> 152.91 | F9: =P26 -> 126.33 | G9: =P27 -> 74.72 | H9: =P28 -> 53.72 | I9: =P29 -> -101.79 | J9: =P30 -> 118.79 | K9: =MEDIAN(C9:J9) -> 96.755
B11: 数据源：2020.9-2026.3 PS倍数
B13: 可比公司
C14: 富创精密 | D14: 先锋精科 | E14: 神工股份 | F14: 凯德石英 | G14: 江丰电子 | H14: 英杰电气 | I14: 机器人 | J14: 新莱应材 | K14: 中位数
B15: -1倍标准差 | C15: =C16-N32 -> 1.9346857 | D15: =D16-N32 -> 6.1946857 | E15: =E16-N32 -> 14.194686 | F15: =F16-N32 -> 3.6546857 | G15: =G16-N32 -> 2.4296857 | H15: =H16-N32 -> 3.8196857 | I15: =I16-N32 -> 0.85468565 | J15: =J16-N32 -> 0.38468565 | K15: =MEDIAN(C15:J15) -> 3.0421857
B16: 中位数 | C16: =N23 -> 6.38 | D16: =N24 -> 10.64 | E16: =N25 -> 18.64 | F16: =N26 -> 8.1 | G16: =N27 -> 6.875 | H16: =N28 -> 8.265 | I16: =N29 -> 5.3 | J16: =N30 -> 4.83 | K16: =MEDIAN(C16:J16) -> 7.4875
B17: +1倍标准差 | C17: =C16+N32 -> 10.825314 | D17: =D16+N32 -> 15.085314 | E17: =E16+N32 -> 23.085314 | F17: =F16+N32 -> 12.545314 | G17: =G16+N32 -> 11.320314 | H17: =H16+N32 -> 12.710314 | I17: =I16+N32 -> 9.7453143 | J17: =J16+N32 -> 9.2753143 | K17: =MEDIAN(C17:J17) -> 11.932814
B18: 最新 | C18: =M23 -> 8.07 | D18: =M24 -> 10.19 | E18: =M25 -> 32.06 | F18: =M26 -> 10.93 | G18: =M27 -> 9 | H18: =M28 -> 7.14 | I18: =M29 -> 6.57 | J18: =M30 -> 7.01 | K18: =MEDIAN(C18:J18) -> 8.535
B20: 二级市场 | S20: 中位数 | AA20: 1.15
A22: 类型 | B22: 公司名称 | C22: 股票代码 | D22: 交易所 | E22: 最新市值（亿元） | F22: 2024年收入（万元） | G22: 2024年净利润 | H22: 2025上半年/三季报收入 | I22: 2025上半年/三季报净利润 | J22: 25年预计收入 | K22: 25年收入VS 24年收入 | L22: PSG | M22: P/S倍数（最新） | N22: P/S倍数（中位数） | O22: P/S倍数（标准差） | P22: P/E倍数（最新） | Q22: P/E倍数（中位数） | R22: P/E倍数（标准差） | S22: 主要业务概述
A23: 二级市场可比公司 | B23: 富创精密 | C23: 688409 | D23: 上交所 | E23: 278.93 | F23: 303956.79 | G23: 16500.874 | H23: 273015.27 | I23: 2615.9516 | J23: 399542 | K23: =J23/F23 -> 1.3144697 | L23: =M23/K23 -> 6.1393579 | M23: 8.07 | N23: 6.38 | O23: 4.8951337 | P23: 553.41 | Q23: 89.89 | R23: 136.84141 | S23: 半导体设备的精密零部件制造。
B24: 先锋精科 | C24: 688605 | D24: 上交所 | E24: 125.88 | F24: 113577.41 | G24: 21394.619 | H24: 96855.959 | I24: 16183.851 | K24: =J24/F24 -> 0 | L24: =M24/K24 -> #DIV/0! | M24: 10.19 | N24: 10.64 | O24: 1.6002918 | P24: 62.72 | Q24: 63.8 | R24: 6.4852612 | S24: 半导体刻蚀和薄膜沉积设备细分领域关键零部件的精密制造。
B25: 神工股份 | C25: 688233 | D25: 上交所 | E25: 129.72 | F25: 30272.951 | G25: 4674.8283 | H25: 31599.983 | I25: 8248.8071 | J25: 45275 | K25: =J25/F25 -> 1.4955595 | L25: =M25/K25 -> 21.436793 | M25: 32.06 | N25: 18.64 | O25: 7.5447225 | P25: 152.91 | Q25: 51.14 | R25: 2241.8892 | S25: 集成电路刻蚀用单晶硅材料的研发、生产和销售。
B26: 凯德石英 | C26: 835179 | D26: 北交所 | E26: 32.42 | F26: 30630.353 | G26: 4032.7796 | H26: 22212.414 | I26: 2839.6053 | J26: 31400 | K26: =J26/F26 -> 1.0251269 | L26: =M26/K26 -> 10.662094 | M26: 10.93 | N26: 8.1 | O26: 2.0298768 | P26: 126.33 | Q26: 34.87 | R26: 32.645494 | S26: 石英仪器、石英管道、石英舟等石英玻璃制品的生产、研发和销售
B27: 江丰电子 | C27: 300666 | D27: 深交所 | E27: 384.45 | F27: 360496.28 | G27: 27367.799 | H27: 329115.62 | I27: 36138.285 | J27: 458709 | K27: =J27/F27 -> 1.2724375 | L27: =M27/K27 -> 7.0730388 | M27: 9 | N27: 6.875 | O27: 1.8255563 | P27: 74.72 | Q27: 63.54 | R27: 22.328348 | S27: 高纯溅射靶材的研发、生产和销售业务
B28: 英杰电气 | C28: 300820 | D28: 深交所 | E28: 114.28 | F28: 178026.95 | G28: 33535.707 | H28: 114974.47 | I28: 19624.596 | J28: 183600 | K28: =J28/F28 -> 1.0313045 | L28: =M28/K28 -> 6.9232702 | M28: 7.14 | N28: 8.265 | O28: 3.4954058 | P28: 53.72 | Q28: 40.15 | R28: 13.199694 | S28: 以功率控制电源、特种电源为代表的工业电源设备的研发、生产、销售
B29: 机器人 | C29: 300024 | D29: 深交所 | E29: 258.01 | F29: 413848.53 | G29: -19652.263 | H29: 221848.12 | I29: -15475.464 | K29: =J29/F29 -> 0 | L29: =M29/K29 -> #DIV/0! | M29: 6.57 | N29: 5.3 | O29: 1.3027723 | P29: -101.79 | Q29: -22.44 | R29: 268.79983 | S29: 零部件、机器人、特种机器人及工业4.0
B30: 新莱应材 | C30: 300260 | D30: 深交所 | E30: 206.15 | F30: 284901.07 | G30: 22625.043 | H30: 225458.76 | I30: 14452.008 | J30: 298118 | K30: =J30/F30 -> 1.0463913 | L30: =M30/K30 -> 6.6992147 | M30: 7.01 | N30: 4.83 | O30: 1.6868675 | P30: 118.79 | Q30: 49.96 | R30: 26.43713 | S30: 以高纯不锈钢为母材之高洁净应用材料研发、生产与销售
I31: 中位数 | J31: =MEDIAN(J23:J30) -> 240859 | K31: =MEDIAN(K23:K30) -> 1.0388479 | L31: 2.9864506 | M31: 中位数（PS) | N31: =MEDIAN(N23:N30) -> 7.4875 | P31: 中位数（PE) | Q31: =MEDIAN(Q23:Q30) -> 50.55
I32: 标准差 | J32: =STDEV(J23:J30) -> 179547.66 | K32: =STDEV(K23:K30) -> 0.57811108 | L32: 3.3413656 | M32: 标准差 | N32: =STDEV(N23:N30) -> 4.4453143 | P32: 标准差 | Q32: =STDEV(Q23:Q30) -> 32.58834
I33: 平均数 | J33: =AVERAGE(J23:J30) -> 236107.33 | K33: =AVERAGE(K23:K30) -> 0.89816119 | L33: 4.5261039
C35: PS | D35: 业务类型 | E35: 2025年预期收入（亿元） | F35: PS估值 | K35: PE | L35: 业务类型 | M35: 2025年预期净利润（亿元） | N35: PE估值 | P35: 备注 (参考二级市场 PE倍数*流动性折扣)
F36: 下限（亿元） | G36: 上限（亿元） | N36: 下限（亿元） | O36: 上限（亿元）
D37: 模块制造+系统制造 | E37: 4.14 | F37: =E37*K15 -> 12.594649 | G37: =E37*K16 -> 30.99825 | L37: 模块制造+系统制造 | M37: 0.87 | N37: =M37*K6 -> 15.626644 | O37: =M37*K7 -> 43.9785 | P37: 下限：14倍PS 上限：46倍PS
D38: 其他 | E38: 0.18 | F38: =E38*4 -> 0.72 | G38: =E38*9 -> 1.62
D39: 合计 | E39: =SUM(E37:E38) -> 4.32 | F39: =SUM(F37:F38) -> 13.314649 | G39: =SUM(G37:G38) -> 32.61825 | L39: 合计 | M39: =SUM(M37:M38) -> 0.87 | N39: =SUM(N37:N38) -> 15.626644 | O39: =SUM(O37:O38) -> 43.9785
C44: PSG | D44: 业务类型 | E44: 2025年预期收入（亿元） | F44: PSG估值 | H44: 备注 (参考二级市场 PSG倍数)
F45: 下限（亿元） | G45: 上限（亿元）
H46: 下限：倍PS 上限：倍PS
D48: 合计

Sheet 二级可比公司三费费率估算 
A1: 富创精密 | B1: 2025三季报 | C1: =C42 -> 2024 年报 | D1: =D42 -> 2023 年报 | E1: =E42 -> 2022 年报 | F1: =F42 -> 2021 年报 | G1: =G42 -> 2020 年报 | H1: =H42 -> 2019 年报 | M1: 中位数 | N1: =MEDIAN(J17,J22,J27,J32,J37,J73,J2,J7,J12) -> 0.023790115 | P1: 行业中位数 | Q1: 0.055
A2: 销售费用 | B2: 0.021964119 | C2: 0.01994221 | D2: 0.017722665 | E2: 0.018647772 | F2: 0.018548425 | G2: 0.025373089 | H2: 0 | J2: =MEDIAN(C2:H2) -> 0.018598099 | N2: =MEDIAN(J18,J23,J28,J33,J38,,J74,J3,J8,J13) -> 0.07510577 | Q2: 0.0749
A3: 管理费用 | B3: 0.1148805 | C3: 0.1124347 | D3: 0.10687841 | E3: 0.072094494 | F3: 0.077196683 | G3: 0.073014857 | H3: 0 | J3: =MEDIAN(C3:H3) -> 0.07510577 | N3: =MEDIAN(J19,J24,J29,J34,J39,J75,J4,J9,J14) -> 0.065496062 | Q3: 0.0756
A4: 研发费用 | B4: 0.071530468 | C4: 0.072838676 | D4: 0.099729256 | E4: 0.07889362 | F4: 0.088003936 | G4: 0.076746218 | H4: 0 | J4: =MEDIAN(C4:H4) -> 0.077819919
A6: 先锋精科 | B6: 2025三季报 | C6: =C1 -> 2024 年报 | D6: =D1 -> 2023 年报 | E6: =E1 -> 2022 年报 | F6: =F1 -> 2021 年报 | G6: =G1 -> 2020 年报 | H6: =H1 -> 2019 年报
A7: 销售费用 | B7: 0.0044200687 | C7: 0.0058477298 | D7: 0.0090002652 | E7: 0.010471385 | F7: 0.012151836 | G7: 0.019547476 | H7: 0 | J7: =MEDIAN(C7:H7) -> 0.009735825
A8: 管理费用 | B8: 0.041294516 | C8: 0.042892596 | D8: 0.06508302 | E8: 0.057644349 | F8: 0.054857819 | G8: 0.45005835 | H8: 0 | J8: =MEDIAN(C8:H8) -> 0.056251084
A9: 研发费用 | B9: 0.055357461 | C9: 0.056422488 | D9: 0.065102922 | E9: 0.065942516 | F9: 0.050846469 | G9: 0.066558271 | H9: 0 | J9: =MEDIAN(C9:H9) -> 0.060762705
A11: 神工股份 | B11: =B6 -> 2025三季报 | C11: =C6 -> 2024 年报 | D11: =D6 -> 2023 年报 | E11: =E6 -> 2022 年报 | F11: =F6 -> 2021 年报 | G11: =G6 -> 2020 年报 | H11: =H6 -> 2019 年报
A12: 销售费用 | B12: 0.016747479 | C12: 0.019592408 | D12: 0.031692206 | E12: 0.0090387057 | F12: 0.0095184516 | G12: 0.015381772 | H12: 0 | J12: =MEDIAN(C12:H12) -> 0.012450112
A13: 管理费用 | B13: 0.070224412 | C13: 0.12023936 | D13: 0.27565295 | E13: 0.073005258 | F13: 0.07441852 | G13: 0.11920145 | H13: 0 | J13: =MEDIAN(C13:H13) -> 0.096809984
A14: 研发费用 | B14: 0.067547195 | C14: 0.082608071 | D14: 0.16637094 | E14: 0.073021578 | F14: 0.073795802 | G14: 0.093187574 | H14: 0 | J14: =MEDIAN(C14:H14) -> 0.078201936
A16: 凯德石英 | B16: 2025三季报 | C16: =C11 -> 2024 年报 | D16: =D11 -> 2023 年报 | E16: =E11 -> 2022 年报 | F16: =F11 -> 2021 年报 | G16: =G11 -> 2020 年报 | H16: =H11 -> 2019 年报
A17: 销售费用 | B17: 0.020823044 | C17: 0.018691592 | D17: 0.019619275 | E17: 0.019818954 | F17: 0.022613091 | G17: 0.015962076 | H17: 0 | J17: =MEDIAN(C17:H17) -> 0.019155433
A18: 管理费用 | B18: 0.17659047 | C18: 0.18366163 | D18: 0.13236743 | E18: 0.11892199 | F18: 0.10226884 | G18: 0.078579374 | H18: 0 | J18: =MEDIAN(C18:H18) -> 0.11059542
A19: 研发费用 | B19: 0.069565617 | C19: 0.064692046 | D19: 0.075957541 | E19: 0.082514522 | F19: 0.065486706 | G19: 0.061447448 | H19: 0 | J19: =MEDIAN(C19:H19) -> 0.065089376
A21: 江丰电子 | B21: 2025三季报 | C21: =C16 -> 2024 年报 | D21: =D16 -> 2023 年报 | E21: =E16 -> 2022 年报 | F21: =F16 -> 2021 年报 | G21: =G16 -> 2020 年报 | H21: =H16 -> 2019 年报
A22: 销售费用 | B22: 0.026502176 | C22: 0.031794863 | D22: 0.033679163 | E22: 0.033129441 | F22: 0.035678366 | G22: 0.037481614 | H22: 0 | J22: =MEDIAN(C22:H22) -> 0.033404302
A23: 管理费用 | B23: 0.064743174 | C23: 0.075815734 | D23: 0.087157768 | E23: 0.081551764 | F23: 0.072304211 | G23: 0.078145196 | H23: 0 | J23: =MEDIAN(C23:H23) -> 0.076980465
A24: 研发费用 | B24: 0.058975536 | C24: 0.060275185 | D24: 0.066022575 | E24: 0.053164739 | F24: 0.061647793 | G24: 0.0632733 | H24: 0 | J24: =MEDIAN(C24:H24) -> 0.060961489
A26: 英杰电气 | B26: 2025三季报 | C26: =C21 -> 2024 年报 | D26: =D21 -> 2023 年报 | E26: =E21 -> 2022 年报 | F26: =F21 -> 2021 年报 | G26: =G21 -> 2020 年报 | H26: =H21 -> 2019 年报
A27: 销售费用 | B27: 0.046868927 | C27: 0.046297204 | D27: 0.036419252 | E27: 0.040487854 | F27: 0.05890571 | G27: 0.051297965 | H27: 0 | J27: =MEDIAN(C27:H27) -> 0.043392529
A28: 管理费用 | B28: 0.032160879 | C28: 0.033120379 | D28: 0.029850226 | E28: 0.034481799 | F28: 0.045995463 | G28: 0.051787619 | H28: 0 | J28: =MEDIAN(C28:H28) -> 0.033801089
A29: 研发费用 | B29: 0.096441236 | C29: 0.076739336 | D29: 0.055066158 | E29: 0.053742156 | F29: 0.07776347 | G29: 0.080982437 | H29: 0 | J29: =MEDIAN(C29:H29) -> 0.065902747
A31: 机器人 | B31: 2025三季报 | C31: =C26 -> 2024 年报 | D31: =D26 -> 2023 年报 | E31: =E26 -> 2022 年报 | F31: =F26 -> 2021 年报 | G31: =G26 -> 2020 年报 | H31: =H26 -> 2019 年报
A32: 销售费用 | B32: 0.039455462 | C32: 0.02801972 | D32: 0.032304988 | E32: 0.028829875 | F32: 0.026841136 | G32: 0.034160012 | H32: 0 | J32: =MEDIAN(C32:H32) -> 0.028424798
A33: 管理费用 | B33: 0.10048091 | C33: 0.074492834 | D33: 0.08473202 | E33: 0.10649768 | F33: 0.10227642 | G33: 0.11540128 | H33: 0 | J33: =MEDIAN(C33:H33) -> 0.09350422
A34: 研发费用 | B34: 0.067337285 | C34: 0.054815998 | D34: 0.049831002 | E34: 0.097687207 | F34: 0.093177464 | G34: 0.16892901 | H34: 0 | J34: =MEDIAN(C34:H34) -> 0.073996731
A36: 新莱应材 | B36: 2025三季报 | C36: =C31 -> 2024 年报 | D36: =D31 -> 2023 年报 | E36: =E31 -> 2022 年报 | F36: =F31 -> 2021 年报 | G36: =G31 -> 2020 年报 | H36: =H31 -> 2019 年报
A37: 销售费用 | B37: 0.060988094 | C37: 0.058932527 | D37: 0.058902941 | E37: 0.047995467 | F37: 0.057122565 | G37: 0.067967265 | H37: 0 | J37: =MEDIAN(C37:H37) -> 0.058012753
A38: 管理费用 | B38: 0.046580537 | C38: 0.044878701 | D38: 0.040087037 | E38: 0.039580558 | F38: 0.040612198 | G38: 0.056136244 | H38: 0 | J38: =MEDIAN(C38:H38) -> 0.040349618
A39: 研发费用 | B39: 0.038639439 | C39: 0.043226443 | D39: 0.040696169 | E39: 0.036572922 | F39: 0.036177256 | G39: 0.048976106 | H39: 0 | J39: =MEDIAN(C39:H39) -> 0.038634546
B41: 半年报%因收入波动因此偏高，暂不纳入进统计
A42: 销售费用 | C42: 2024 年报 | D42: 2023 年报 | E42: 2022 年报 | F42: 2021 年报 | G42: 2020 年报 | H42: 2019 年报 | J42: 中位数
A43: =A1 -> 富创精密 | C43: =C2 -> 0.01994221 | D43: =D2 -> 0.017722665 | E43: =E2 -> 0.018647772 | F43: =F2 -> 0.018548425 | G43: =G2 -> 0.025373089 | H43: =H2 -> 0 | J43: =MEDIAN(C43:H50) -> 0.019880582
A44: =A6 -> 先锋精科 | C44: =C7 -> 0.0058477298 | D44: =D7 -> 0.0090002652 | E44: =E7 -> 0.010471385 | F44: =F7 -> 0.012151836 | G44: =G7 -> 0.019547476 | H44: =H7 -> 0
A45: =A11 -> 神工股份 | C45: =C12 -> 0.019592408 | D45: =D12 -> 0.031692206 | E45: =E12 -> 0.0090387057 | F45: =F12 -> 0.0095184516 | G45: =G12 -> 0.015381772 | H45: =H12 -> 0
A46: =A16 -> 凯德石英 | C46: =C17 -> 0.018691592 | D46: =D17 -> 0.019619275 | E46: =E17 -> 0.019818954 | F46: =F17 -> 0.022613091 | G46: =G17 -> 0.015962076 | H46: =H17 -> 0
A47: =A21 -> 江丰电子 | C47: =C22 -> 0.031794863 | D47: =D22 -> 0.033679163 | E47: =E22 -> 0.033129441 | F47: =F22 -> 0.035678366 | G47: =G22 -> 0.037481614 | H47: =H22 -> 0
A48: =A26 -> 英杰电气 | C48: =C27 -> 0.046297204 | D48: =D27 -> 0.036419252 | E48: =E27 -> 0.040487854 | F48: =F27 -> 0.05890571 | G48: =G27 -> 0.051297965 | H48: =H27 -> 0
...

Sheet 可比公司毛利
B1: 富创精密 | E1: 先锋精科 | H1: 神工股份 | K1: 凯德石英 | N1: 江丰电子 | Q1: 英杰电气 | T1: 机器人 | W1: 新莱应材
B2: SHSE:688409 | E2: SHSE:688605 | H2: SHSE:688233 | K2: 北交所：835179 | N2: SZSE:300666 | Q2: SZSE:300820 | T2: SZSE:300024 | W2: SZSE:300260
A3: 人民币千元 | B3: 2023 | C3: 2024 | D3: 2025.1-9 | E3: 2023 | F3: 2024 | G3: 2025.1-9 | H3: 2023 | I3: 2024 | J3: 2025.1-9 | K3: 2023 | L3: 2024 | M3: 2025.1-9 | N3: 2023 | O3: 2024 | P3: 2025.1-9 | Q3: 2023 | R3: 2024 | S3: 2025.1-9 | T3: 2023 | U3: 2024 | V3: 2025.1-9 | W3: 2023 | X3: 2024 | Y3: 2025.1-9
A4: 营业收入 | B4: 206575.59 | C4: 303956.79 | D4: 273015.27 | E4: 55771.69 | F4: 113577.41 | G4: 96855.96 | H4: 13503.32 | I4: 30272.95 | J4: 31599.98 | K4: 25968.85 | L4: 30630.35 | M4: 22212.41 | N4: 260160.86 | O4: 360496.28 | P4: 329115.62 | Q4: 176980.57 | R4: 178026.95 | S4: 114974.47 | T4: 396659.49 | U4: 413848.53 | V4: 221848.12 | W4: 271139.77 | X4: 284901.07 | Y4: 225458.76
A5: 毛利 | B5: 52055.23 | C5: 78410.4 | D5: 68094.82 | E5: 16694.84 | F5: 38425.16 | G5: 29176.53 | H5: 11.5 | I5: 10200.12 | J5: 13276.77 | K5: 10102.11 | L5: 12762.62 | M5: 9732.7 | N5: 75973.17 | O5: 101568.34 | P5: 95220.89 | Q5: 65880.95 | R5: 68547.44 | S5: 41143.79 | T5: 55066.88 | U5: 60516.53 | V5: 30584.76 | W5: 69370.94 | X5: 73266.84 | Y5: 53687.13
A6: 毛利率 | B6: 0.2519912 | C6: 0.25796561 | D6: 0.24941762 | E6: 0.29934255 | F6: 0.33831692 | G6: 0.30123629 | H6: 0.00085164241 | I6: 0.33693842 | J6: 0.42015122 | K6: 0.38900875 | L6: 0.41666582 | M6: 0.43816497 | N6: 0.29202383 | O6: 0.28174588 | P6: 0.28932352 | Q6: 0.37224962 | R6: 0.38503968 | S6: 0.35785153 | T6: 0.13882658 | U6: 0.14622869 | V6: 0.13786351 | W6: 0.25584937 | X6: 0.2571659 | Y6: 0.23812395
A7: 主营业务介绍 | B7: 成立于 2008 年，总部位于辽宁沈阳。专注于半导体设备精密零部件的研发、生产与销售，是国内半导体设备精密零部件领军企业，产品广泛服务于国内外半导体设备龙头厂商。公司提供全系列精密零部件产品，包括反应腔体、内衬、加热器、匀气盘等工艺零部件，腔体盖板、法兰、信号箱等结构零部件，气柜、气体管路、阀门等气体传输系统，以及腔体模组、阀体模组等模组产品。同时提供配套特种工艺与表面处理技术，包括含氟涂层、致密 YO 涂层、N 系列 / O 系列膜层等关键制程解决方案。此外，公司还提供集成化制造服务，涵盖从精密加工、焊接到表面处理的一站式交付，以及面向 7nm 及以下先进制程的定制化工艺组件与整体解决方案。它服务于刻蚀、沉积、光刻、清洗等半导体设备厂商，覆盖集成电路制造、泛半导体及先进工艺领域，客户包括中微公司、北方华创、东京电子（TEL）、应用材料（AMAT）等全球龙头。 | E7: 成立于 2011 年，总部位于江苏靖江。是国内半导体刻蚀与薄膜沉积设备关键精密零部件的核心供应商，专注于先进制程高精密金属部件制造，在国产设备供应链中占据重要地位。公司提供全系列关键工艺部件，包括腔体、内衬、加热器、匀气盘等刻蚀设备核心反应区部件，以及喷嘴、气体分配环、接地环、射频连接板等精密工艺组件，同时提供法兰板、盖板、信号箱等结构部件。它还提供定制化精密加工与焊接服务，针对复杂结构部件实现高精度成型与密封集成，以及联合研发与协同测试服务，深度参与客户设备从设计验证到量产交付的全流程。此外，公司提供多材质适配的高精密部件解决方案，覆盖不锈钢、镍基合金、钛合金等多种材料，满足不同工艺环境的严苛需求。它服务于国内主流半导体设备厂商与晶圆制造企业，覆盖刻蚀、PVD/CVD 沉积等核心设备领域，客户包括中微公司、北方华创、拓荆科技、华海清科、屹唐股份等，同时逐步拓展航空航天、医疗设备等高端制造领域。 | H7: 成立于 2013 年，总部位于辽宁锦州。专注于半导体级单晶硅材料及硅零部件的研发、生产与销售，是全球刻蚀用大直径硅材料龙头，已转型为 “材料 + 零部件” 一体化平台型企业。公司提供全系列大直径硅材料产品，覆盖 14–22 英寸刻蚀用单晶硅，其中 22 英寸产品全球市占率超 80%，纯度达 11 个 9，满足 7nm 及以下先进制程需求。同时提供硅电极、硅环、硅罩等刻蚀设备核心硅零部件，具备 “耗材” 属性，与晶圆厂开工率强相关。此外，公司提供半导体大尺寸硅片产品，包括 8 英寸轻掺低缺陷硅片，正加速推进国内主流芯片制造厂认证，以及从晶体生长到硅电极加工的全链条制造服务，实现材料与部件协同优化。它服务于集成电路制造、刻蚀设备及存储芯片领域，客户包括长江存储、长鑫存储、中芯国际、北方华创等国内龙头厂商。 | K7: 成立于 1997 年，总部位于北京通州。专注于半导体与光伏用石英玻璃制品的研发、生产与销售，是国内半导体石英制品龙头，也是内资企业中首家通过中芯国际 12 英寸产线认证的厂商。公司提供全系列半导体石英制品，包括石英舟、石英钟罩、石英内管、石英保温筒、石英环、石英管道等，覆盖扩散、氧化、刻蚀、清洗等全工艺环节。同时提供光伏石英制品，包括太阳能用石英舟、石英塔、挡板等，以及定制化石英玻璃制品与精密加工服务，满足不同产线规格需求。此外，公司提供高纯石英管与石英砂原料配套服务，支撑高端石英制品制造，还参与制定《半导体硅片清洗用石英槽》《集成电路刻蚀设备用石英环》等行业团体标准。它服务于半导体芯片制造、光伏太阳能及泛半导体领域，客户包括中芯国际、北方华创、捷佳伟创、长江存储等，产品远销德国、美国、中国台湾等地区。 | N7: 成立于 2005 年，总部位于浙江宁波。专注于超高纯金属溅射靶材与半导体精密零部件的研发、生产与销售，是全球超高纯金属靶材龙头，构建 “靶材 + 零部件” 双轮驱动战略格局。公司提供全系列超高纯金属溅射靶材，包括铝、钛、钽、铜、钨及合金靶材，覆盖 90–3nm 全制程，是 PVD 工艺核心耗材。同时提供半导体精密零部件，包括硅电极、匀气盘、加热器、静电吸盘等刻蚀与沉积设备核心部件，以及平板显示靶材与太阳能电池制造用靶材。此外，公司提供配套材料与组件解决方案，包括 CMP 材料、超高纯金属原材料，以及联合研发与供应链协同服务，通过收购凯德石英强化石英部件与半导体材料协同优势。它服务于半导体制造、平板显示、太阳能电池及仪器制造领域，客户包括台积电、中芯国际、SK 海力士、京东方、英特尔等全球龙头。 | Q7: 成立于 1996 年，总部位于四川德阳。专注于工业电源设备的研发、生产与销售，是国内综合性工业电源领军企业，同时布局新能源充电桩与特种电源领域。公司提供全系列功率控制电源，包括多晶硅还原炉电源、单晶炉电源、蓝宝石炉电源、碳化硅炉电源、功率控制器等，覆盖光伏、半导体、核电等新兴行业生产设备需求。同时提供特种电源，包括射频电源（适配刻蚀、PECVD 等半导体工艺）、测试电源、匹配器，以及新能源汽车充电桩 / 站、制氢电源等产品。此外，公司提供集成化电源系统解决方案，包括可编程直流电源、电力调整器、周波控制器，以及定制化电源设计与运维服务，多项产品通过欧盟 CE 认证。它服务于光伏、半导体、核电、环保、新能源汽车、石油化工、冶金等多领域，客户包括通威、协鑫、中微、北方华创、比亚迪、小鹏等龙头企业。 | T7: 成立于 2000 年，总部位于辽宁沈阳。是国内机器人产业领军企业，专注于工业机器人、移动机器人、特种机器人及智能制造系统集成，产品出口全球 40 多个国家和地区。公司提供全系列工业机器人，包括六轴机器人（焊接、切割、搬运、装配、喷涂、码垛）、并联机器人、SCARA 机器人等，适配多场景自动化生产。同时提供移动机器人，包括 AGV/AMR（装配、搬运、清洁、仓储物流），以及特种机器人，包括核电、洁净、防爆、巡检、医疗服务机器人等。此外，公司提供智能制造系统解决方案，包括自动化产线、智能仓储、数字化工厂整体方案，以及焊接接缝步进器、拣选器等专用设备，前瞻布局具身智能机器人全矩阵产品研发。它服务于汽车制造、3C 电子、光伏、锂电、物流、核电、医药、航空航天等国民经济重点领域，客户包括《财富》世界 500 强中 45% 的制造业企业，累计为 4000 余家企业提供服务。 | W7: 成立于 2000 年，总部位于江苏昆山。是国内高洁净 / 超高纯应用材料领域领先企业，产品覆盖半导体、生物医药、食品安全三大核心领域，是国内唯一量产半导体级真空阀门 / 管路系统的企业。公司提供泛半导体领域高洁净 / 超高纯产品，包括 AdvanTorr 系列真空腔体、法兰、传输阀、气柜，NanoPure 系列超高纯气体管路、阀门，泄漏率低至 10⁻⁹Pa・m³/s，满足 7nm 及以下先进制程需求。同时提供生物医药领域无菌流体系统，包括 ASME BPE 认证的无菌阀门、管道、泵，以及食品饮料领域无菌包装材料与卫生级泵阀、管道，满足 “零污染” 生产要求。此外，公司提供液冷解决方案，包括 CDU 冷液分配单元、快接头等核心组件，已进入英伟达 GB200 供应链验证，以及定制化洁净系统集成服务，覆盖从方案设计到安装运维的全流程。它服务于半导体制造、生物制药、液态食品加工、液冷数据中心等领域，客户包括中芯国际、长江存储、北方华创、辉瑞、药明生物、伊利、蒙牛、英特尔等全球龙头。

Sheet 可比公司营运情况
B2: 最近 12 个月营收（TTM）亿元 | C2: 毛利率（%） | D2: 净利率 | E2: 应收账款期末余额(万元) | F2: 预收账款期末余额（万元） | G2: 净应收（万元） | H2: DSO | I2: 应付账款余额（万元） | J2: 预付账款余额（万元） | K2: 净应付（万元） | L2: DPO | M2: 期初存货余额 | N2: 期末存货余额 | O2: 平均存货（期初存货余额+期末存货余额)/2 | P2: 存货周转天数（同花顺数字）
A3: 富创精密 | B3: 12.354428 | C3: 30.12 | D3: 16.71 | E3: 40704.721 | F3: 0 | G3: =E3-F3 -> 40704.721 | H3: =360/(B3*10000/G3) -> 118.61091 | I3: 36094.751 | J3: 682.75094 | K3: =I3-J3 -> 35412 | L3: =360/(B3*(100-C3)*1%*10^4/K3) -> 147.66495 | M3: 26637.634 | N3: 29096.646 | O3: =(M3+N3)/2 -> 27867.14 | P3: 111.1752
A4: 先锋精科 | B4: 4.0461985 | C4: 42.02 | D4: 26.1 | E4: 10765.258 | F4: 0 | G4: =E4-F4 -> 10765.258 | H4: =360/(B4*10000/G4) -> 95.781086 | I4: 3760.8068 | J4: 754.62828 | K4: =I4-J4 -> 3006.1785 | L4: =360/(B4*(100-C4)*1%*10^4/K4) -> 46.130894 | M4: 10991.285 | N4: 10431.569 | O4: =(M4+N4)/2 -> 10711.427 | P4: 157.8394
A5: 神工股份 | B5: 2.9651938 | C5: 43.82 | D5: 12.78 | E5: 10499.812 | F5: 0 | G5: =E5-F5 -> 10499.812 | H5: =360/(B5*10000/G5) -> 127.47673 | I5: 5397.3522 | J5: 264.37493 | K5: =I5-J5 -> 5132.9772 | L5: =360/(B5*(100-C5)*1%*10^4/K5) -> 110.92694 | M5: 11203.919 | N5: 11015.486 | O5: =(M5+N5)/2 -> 11109.702 | P5: 240.3632
A6: 凯德石英 | B6: 42.709259 | C6: 28.93 | D6: 10.98 | E6: 112946.82 | F6: 0 | G6: =E6-F6 -> 112946.82 | H6: =360/(B6*10000/G6) -> 95.203838 | I6: 120627.97 | J6: 3778.9137 | K6: =I6-J6 -> 116849.06 | L6: =360/(B6*(100-C6)*1%*10^4/K6) -> 138.586 | M6: 145061.4 | N6: 151132.09 | O6: =(M6+N6)/2 -> 148096.74 | P6: 170.9618
A7: 江丰电子 | B7: 16.009408 | C7: 35.79 | D7: 17.07 | E7: 39598.775 | F7: 0 | G7: =E7-F7 -> 39598.775 | H7: =360/(B7*10000/G7) -> 89.044889 | I7: 12733.669 | J7: 3558.9732 | K7: =I7-J7 -> 9174.6955 | L7: =360/(B7*(100-C7)*1%*10^4/K7) -> 32.130407 | M7: 155594.63 | N7: 135615.91 | O7: =(M7+N7)/2 -> 145605.27 | P7: 532.4394
A8: 英杰电气 | B8: 39.261731 | C8: 13.79 | D8: -6.98 | E8: 140706.84 | F8: 0 | G8: =E8-F8 -> 140706.84 | H8: =360/(B8*10000/G8) -> 129.01739 | I8: 211130.13 | J8: 34458.277 | K8: =I8-J8 -> 176671.85 | L8: =360/(B8*(100-C8)*1%*10^4/K8) -> 187.90692 | M8: 329383.96 | N8: 378444.18 | O8: =(M8+N8)/2 -> 353914.07 | P8: 499.6299
A9: 机器人 | B9: 29.421113 | C9: 23.81 | D9: 6.41 | E9: 89950.787 | F9: 116.7949 | G9: =E9-F9 -> 89833.992 | H9: =360/(B9*10000/G9) -> 109.92187 | I9: 69799.676 | J9: 669.93365 | K9: =I9-J9 -> 69129.742 | L9: =360/(B9*(100-C9)*1%*10^4/K9) -> 111.02234 | M9: 154867.52 | N9: 153537.22 | O9: =(M9+N9)/2 -> 154202.37 | P9: 242.3916
A10: 新莱应材 | B10: 34.548256 | C10: 24.94 | D10: 0.96 | E10: 162597.31 | F10: 0 | G10: =E10-F10 -> 162597.31 | H10: =360/(B10*10000/G10) -> 169.42977 | I10: 64398.663 | J10: 4391.2718 | K10: =I10-J10 -> 60007.391 | L10: =360/(B10*(100-C10)*1%*10^4/K10) -> 83.305287 | M10: 89985.75 | N10: 97148.809 | O10: =(M10+N10)/2 -> 93567.279 | P10: 123.282

Sheet 锐洁利润表
B1: 评阅期间 | D1: 预测期 | K1: 合并利润表
A2: 人民币万元 | B2: 2024年 | C2: 2025年 | D2: 2026年E | E2: Y0Y% | F2: 2027E | G2: Y0Y% | K2: 人民币千元 | L2: 2024年 | M2: 2025年 | N2: 评阅期间合计
A3: 营业收入 | B3: =373202.010400001/10 -> 37320.201 | C3: 43221.542 | D3: =SUM(D4:D8) -> 57800 | F3: 73500 | K3: 营业收入 | L3: 373202.01 | M3: 432215.42 | N3: =SUM(L3,M3) -> 805417.43
A4: Robot | B4: 25758.444 | C4: 28413.643 | D4: 35000 | E4: 0.23180263 | F4: 40000 | G4: 0.14285714 | K4: 营业成本 | L4: -215360.16 | M4: -245144.96 | N4: =SUM(L4,M4) -> -460505.12
A5: aligner | B5: 2391.4975 | C5: 2236.5924 | D5: 3300 | E5: 0.47545883 | F5: 4500 | G5: 0.36363636 | K5: 毛利 | L5: =SUM(L3:L4) -> 157841.85 | M5: =SUM(M3:M4) -> 187070.45 | N5: =SUM(L5,M5) -> 344912.31
A6: EFEM | B6: 5135.509 | C6: 7306.4114 | D6: 12000 | E6: 0.64239314 | F6: 20000 | G6: 0.66666667 | K6: 税金及附加 | L6: -312.41087 | M6: -2252.439 | N6: =SUM(L6,M6) -> -2564.8499
A7: 载台 | B7: 69.097346 | C7: 64.374337 | D7: 2500 | E7: 37.835351 | F7: 3500 | G7: 0.4 | K7: 销售费用 | L7: -16024.355 | M7: -21009.406 | N7: =SUM(L7,M7) -> -37033.761
A8: 其他 | B8: 3965.6534 | C8: 5200.5207 | D8: 5000 | E8: -0.038557817 | F8: 5500 | G8: 0.1 | K8: 管理费用 | L8: -17675.833 | M8: -21590.286 | N8: =SUM(L8,M8) -> -39266.119
A9: YOY% | B9: 0.21090457 | C9: 0.15812725 | D9: 0.33729612 | F9: 0.2716263 | K9: 研发费用 | L9: -43803.072 | M9: -56192.907 | N9: =SUM(L9,M9) -> -99995.979
A10: 营业成本 | B10: -21536.016 | C10: -24514.496 | D10: -33524 | F10: -43365 | G10: 0.29355089 | K10: 财务费用 | L10: -4443.6474 | M10: -1610.2691 | N10: =SUM(L10,M10) -> -6053.9165
A11: Robot | B11: -1526.3081 | C11: -16363.56 | D11: -20300 | F11: -23600 | K11: 信用减值损失 | L11: -3117.4378 | M11: -6154.3458 | N11: -9271.7836
A12: aligner | B12: -1317.8136 | C12: -1174.0352 | D12: -1914 | F12: -2655 | K12: 其他收益 | L12: 16881.215 | M12: 12927.42 | N12: =SUM(L12,M12) -> 29808.636
A13: EFEM | B13: -2843.491 | C13: -4388.9393 | D13: -6960 | F13: -11800 | K13: 营业利润/（亏损） | L13: =SUM(L5:L12) -> 89346.314 | M13: =SUM(M5:M12) -> 91188.221 | N13: =SUM(L13,M13) -> 180534.54
A14: 载台 | B14: -29.947828 | C14: -26.993885 | D14: -1450 | F14: -2065 | K14: 营业外收入 | L14: 38.89393 | M14: 204.71825 | N14: =SUM(L14,M14) -> 243.61218
A15: 其他 | B15: -2081.682 | C15: -2560.9679 | D15: -2900 | F15: -3245 | K15: 营业外支出 | L15: -10.16379 | M15: -67.16343 | N15: =SUM(L15,M15) -> -77.32722
A16: 毛利率 | B16: 0.42293945 | C16: 0.43281763 | D16: =(D10+D3)/D3 -> 0.42 | F16: 0.41 | K16: （利润）/亏损 | L16: =SUM(L13:L15) -> 89375.044 | M16: =SUM(M13:M15) -> 91325.776 | N16: =SUM(L16,M16) -> 180700.82
A17: 运营费用 | B17: -8078.3508 | C17: -10832.902 | D17: -14276.6 | F17: -18228 | K17: 所得税费用 | L17: -10259.757 | M17: -4682.9894 | N17: =SUM(L17,M17) -> -14942.746
A18: 销售费用 | B18: -1602.4355 | C18: -2100.9406 | D18: -3179 | F18: -4042.5 | K18: 净利润/（亏损） | L18: =SUM(L16:L17) -> 79115.288 | M18: =SUM(M16:M17) -> 86642.786 | N18: =SUM(L18,M18) -> 165758.07
A19: 管理费用 | B19: -1767.5833 | C19: -2159.0286 | D19: -3468 | F19: -4410 | K19: KPI
A20: 研发费用 | B20: -4380.3072 | C20: -5619.2907 | D20: -6473.6 | F20: -8305.5 | K20: 毛利率 | L20: =IFERROR(L5/(L$4),0) -> -0.73292041 | M20: =IFERROR(M5/(M$4),0) -> -0.76310135 | N20: =IFERROR(N5/(N$4),0) -> -0.74898691
A21: 信用减值损失 | B21: -328.02478 | C21: -953.64249 | D21: -1156 | F21: -1470 | K21: 销售费用率 | L21: =IFERROR(L7/(L$4),0)*(-1) -> -0.074407239 | M21: =IFERROR(M7/(M$4),0)*(-1) -> -0.08570197 | N21: =IFERROR(N7/(N$4),0)*(-1) -> -0.080419868
A22: 净利润 | B22: 7911.5288 | C22: 8326.0707 | D22: 10218.2 | F22: 12163 | K22: 管理费用率 | L22: =IFERROR(L8/(L$4),0)*(-1) -> -0.082075687 | M22: =IFERROR(M8/(M$4),0)*(-1) -> -0.088071506 | N22: =IFERROR(N8/(N$4),0)*(-1) -> -0.085267497
A23: 净利率 | B23: 0.21199052 | C23: 0.19263706 | D23: 0.17678547 | F23: =F22/F3 -> 0.16548299 | K23: 研发费用率 | L23: =IFERROR(L9/(L$4),0)*(-1) -> -0.20339451 | M23: =IFERROR(M9/(M$4),0)*(-1) -> -0.22922317 | N23: =IFERROR(N9/(N$4),0)*(-1) -> -0.21714412
A24: 销售费用率 | B24: 0.042937482 | C24: 0.048608646 | D24: 0.055 | F24: 0.055 | K24: 净利率 | L24: =IFERROR(L18/(L$4),0) -> -0.3673627 | M24: =IFERROR(M18/(M$4),0) -> -0.3534349 | N24: =IFERROR(N18/(N$4),0) -> -0.35994838
A25: 管理费用率 | B25: 0.047362641 | C25: 0.049952605 | D25: 0.06 | F25: 0.06
A26: 研发费用率 | B26: 0.11737094 | C26: 0.13001134 | D26: 0.112 | F26: 0.113
